
 Sun, 06 Feb 2022 21:18:00 GMT

COMMAND LINE:
 /usr/bin/pyston fasta.pyston-5.pyston 2500000

PROGRAM FAILED 


PROGRAM OUTPUT:

Traceback (most recent call last):
  File "fasta.pyston-5.pyston", line 210, in <module>
    fasta(int(argv[1]))
  File "fasta.pyston-5.pyston", line 176, in fasta
    seed = RawValue('f', 42)
  File "/usr/lib/python3.8-pyston2.3/multiprocessing/context.py", line 124, in RawValue
    from .sharedctypes import RawValue
  File "/usr/lib/python3.8-pyston2.3/multiprocessing/sharedctypes.py", line 10, in <module>
    import ctypes
  File "/usr/lib/python3.8-pyston2.3/ctypes/__init__.py", line 7, in <module>
    from _ctypes import Union, Structure, Array
ImportError: libffi.so.7: cannot open shared object file: No such file or directory
