
Mon, 22 Jun 2015 11:13:16 GMT

COMMAND LINE:
/usr/bin/python3.5 pidigits.python3.5-4.python3.5 2000

PROGRAM FAILED 


PROGRAM OUTPUT:

Traceback (most recent call last):
  File "pidigits.python3.5-4.python3.5", line 8, in <module>
    import gmpy2
ImportError: No module named 'gmpy2'

During handling of the above exception, another exception occurred:

Traceback (most recent call last):
  File "pidigits.python3.5-4.python3.5", line 10, in <module>
    import gmpy_cffi as gmpy2
ImportError: No module named 'gmpy_cffi'
