
Tue, 09 Jul 2019 18:49:37 GMT

COMMAND LINE:
/usr/bin/python3.9 pidigits.python-dev-2.python-dev 10000

PROGRAM FAILED 


PROGRAM OUTPUT:

Traceback (most recent call last):
  File "/home/dundee/workspace/benchmarksgame/bencher/tmp/pidigits/tmp/pidigits.python-dev-2.python-dev", line 8, in <module>
    from gmpy2 import mpz
ModuleNotFoundError: No module named 'gmpy2'

During handling of the above exception, another exception occurred:

Traceback (most recent call last):
  File "/home/dundee/workspace/benchmarksgame/bencher/tmp/pidigits/tmp/pidigits.python-dev-2.python-dev", line 10, in <module>
    from gmpy_cffi import mpz
ModuleNotFoundError: No module named 'gmpy_cffi'
