
 Mon, 25 Jan 2021 21:34:40 GMT

COMMAND LINE:
 /usr/bin/pyston pidigits.pyston-5.pyston 10000

PROGRAM FAILED 


PROGRAM OUTPUT:

Traceback (most recent call last):
  File "pidigits.pyston-5.pyston", line 10, in <module>
    from gmpy2 import xmpz, f_divmod
ModuleNotFoundError: No module named 'gmpy2'

During handling of the above exception, another exception occurred:

Traceback (most recent call last):
  File "pidigits.pyston-5.pyston", line 12, in <module>
    from gmpy_cffi import mpz as xmpz
ModuleNotFoundError: No module named 'gmpy_cffi'
