
Thu, 26 Apr 2018 16:46:12 GMT

COMMAND LINE:
/usr/bin/pypy pidigits.pypy-3.pypy 10000

PROGRAM FAILED 


PROGRAM OUTPUT:

Traceback (most recent call last):
  File "pidigits.pypy-3.pypy", line 13, in <module>
    from gmpy_cffi import mpz
  File "/opt/pypy/site-packages/gmpy_cffi/__init__.py", line 1, in <module>
    from .mpz import mpz
  File "/opt/pypy/site-packages/gmpy_cffi/mpz.py", line 4, in <module>
    from gmpy_cffi.interface import gmp, ffi
  File "/opt/pypy/site-packages/gmpy_cffi/interface.py", line 503, in <module>
    """, libraries=['gmp', 'mpfr', 'mpc'])
  File "/opt/pypy/lib_pypy/cffi/api.py", line 451, in verify
    lib = self.verifier.load_library()
  File "/opt/pypy/lib_pypy/cffi/verifier.py", line 105, in load_library
    return self._load_library()
  File "/opt/pypy/lib_pypy/cffi/verifier.py", line 216, in _load_library
    return self._vengine.load_library()
  File "/opt/pypy/lib_pypy/cffi/vengine_gen.py", line 70, in load_library
    module = backend.load_library(filename, flags)
OSError: Cannot load library /opt/pypy/site-packages/_cffi__g9a660983x9cbb9358.pypy-41.so: libmpfr.so.4: cannot open shared object file: No such file or directory
